<?xml version="1.0" encoding="utf-8"?>
<robot name="nova5_robot">
  <link name="dummy_link"/>
  <link name="base_link">
    <inertial>
      <origin xyz="6.56698714338847E-06 2.73052159273858E-06 0.0698223124889706" rpy="0 0 0" />
      <mass value="1.3106443915978" />
      <inertia ixx="0.00308109148952278" ixy="-4.0369958400766E-08" ixz="5.2607663395944E-07" iyy="0.00309758743296662" iyz="-6.37484696538659E-09" izz="0.00232835367593981" />
    </inertial>
    <visual>
      <origin xyz="0 0 0" rpy="0 0 0" />
      <geometry>
        <mesh filename="package://dobot_rviz/meshes/nova5/base_link.STL" />
      </geometry>
      <material name="">
        <color rgba="0.792156862745098 0.819607843137255 0.933333333333333 1" />
      </material>
    </visual>
    <collision>
      <origin xyz="0 0 0" rpy="0 0 0" />
      <geometry>
        <mesh filename="package://dobot_rviz/meshes/nova5/base_link.STL" />
      </geometry>
    </collision>
  </link>
  <joint name="dummy_joint" type="fixed">
    <parent link="dummy_link" />
    <child link="base_link" />
  </joint>

  <link name="Link1">
    <inertial>
      <origin xyz="9.18642704220017E-06 -0.021770784235076 -0.0261833991373472" rpy="0 0 0" />
      <mass value="1.08090940330212" />
      <inertia ixx="0.00265963193119309" ixy="1.85196348994647E-07" ixz="-3.27720040926316E-07" iyy="0.00247342331575097" iyz="0.000661331129337329" izz="0.00164737186015792" />
    </inertial>
    <visual>
      <origin xyz="0 0 0" rpy="0 0 0" />
      <geometry>
        <mesh filename="package://dobot_rviz/meshes/nova5/Link1.STL" />
      </geometry>
      <material name="">
        <color rgba="0.792156862745098 0.819607843137255 0.933333333333333 1" />
      </material>
    </visual>
    <collision>
      <origin xyz="0 0 0" rpy="0 0 0" />
      <geometry>
        <mesh filename="package://dobot_rviz/meshes/nova5/Link1.STL" />
      </geometry>
    </collision>
  </link>
  <joint name="joint1" type="revolute">
    <origin xyz="0 0 0.240000000000178" rpy="0 0 -1.57" />
    <parent link="base_link" />
    <child link="Link1" />
    <axis xyz="0 0 0.999999999999855" />
    <limit lower="-6.28" upper="6.28" effort="0" velocity="0" />
  </joint>

  <link name="Link2">
    <inertial>
      <origin xyz="-0.19933810729628 -0.00696463483971123 0.109208661556353" rpy="0 0 0" />
      <mass value="2.54585370113969" />
      <inertia ixx="0.00285193319464959" ixy="-0.00212784400881843" ixz="-0.00109906472415148" iyy="0.0636767872390402" iyz="-3.83872488712299E-05" izz="0.0643005121111712" />
    </inertial>
    <visual>
      <origin xyz="0 0 0" rpy="0 0 0" />
      <geometry>
        <mesh filename="package://dobot_rviz/meshes/nova5/Link2.STL" />
      </geometry>
      <material name="">
        <color rgba="0.792156862745098 0.819607843137255 0.933333333333333 1" />
      </material>
    </visual>
    <collision>
      <origin xyz="0 0 0" rpy="0 0 0" />
      <geometry>
        <mesh filename="package://dobot_rviz/meshes/nova5/Link2.STL" />
      </geometry>
    </collision>
  </link>
  <joint name="joint2" type="revolute">
    <origin xyz="0 0 0" rpy="-1.57080287682252 1.53586622836832 3.14159265358979" />
    <parent link="Link1" />
    <child link="Link2" />
    <axis xyz="0 0 1" />
    <limit lower="-3.14" upper="3.14" effort="0" velocity="0" />
  </joint>

  <link name="Link3">
    <inertial>
      <origin xyz="-0.152357289724291 -0.0053571688729055 0.0198991511385547" rpy="0 0 0" />
      <mass value="1.40745649848125" />
      <inertia ixx="0.00100801309674517" ixy="-0.00077546601599374" ixz="4.43267247578911E-05" iyy="0.0231741793950995" iyz="1.31338010910521E-06" izz="0.02359962285525" />
    </inertial>
    <visual>
      <origin xyz="0 0 0" rpy="0 0 0" />
      <geometry>
        <mesh filename="package://dobot_rviz/meshes/nova5/Link3.STL" />
      </geometry>
      <material name="">
        <color rgba="0.792156862745098 0.819607843137255 0.933333333333333 1" />
      </material>
    </visual>
    <collision>
      <origin xyz="0 0 0" rpy="0 0 0" />
      <geometry>
        <mesh filename="package://dobot_rviz/meshes/nova5/Link3.STL" />
      </geometry>
    </collision>
  </link>
  <joint name="joint3" type="revolute">
    <origin xyz="-0.399756009268664 -0.0139690033141953 0" rpy="0 0 0" />
    <parent link="Link2" />
    <child link="Link3" />
    <axis xyz="0 0 1" />
    <limit lower="-2.79" upper="2.79" effort="0" velocity="0" />
  </joint>

  <link name="Link4">
    <inertial>
      <origin xyz="-6.37112093033953E-06 -0.0227590499933018 -0.0202381689250349" rpy="0 0 0" />
      <mass value="0.439666284541787" />
      <inertia ixx="0.000634738696193051" ixy="1.33529119545257E-08" ixz="2.91412587537874E-08" iyy="0.00045014395177395" iyz="0.000210919680187578" izz="0.000480311391216564" />
    </inertial>
    <visual>
      <origin xyz="0 0 0" rpy="0 0 0" />
      <geometry>
        <mesh filename="package://dobot_rviz/meshes/nova5/Link4.STL" />
      </geometry>
      <material name="">
        <color rgba="0.792156862745098 0.819607843137255 0.933333333333333 1" />
      </material>
    </visual>
    <collision>
      <origin xyz="0 0 0" rpy="0 0 0" />
      <geometry>
        <mesh filename="package://dobot_rviz/meshes/nova5/Link4.STL" />
      </geometry>
    </collision>
  </link>
  <joint name="joint4" type="revolute">
    <origin xyz="-0.329798707647103 -0.0115244277211674 0.134999532858734" rpy="0 0 -1.53586622840712" />
    <parent link="Link3" />
    <child link="Link4" />
    <axis xyz="0 0 1" />
    <limit lower="-6.28" upper="6.28" effort="0" velocity="0" />
  </joint>

  <link name="Link5">
    <inertial>
      <origin xyz="-1.27925890990664E-06 0.00190911597991161 -0.0076111865696753" rpy="0 0 0" />
      <mass value="0.574835130260071" />
      <inertia ixx="0.000663176880523558" ixy="1.30179448329138E-08" ixz="1.22670358756949E-08" iyy="0.000397520749670404" iyz="-0.00012026389265228" izz="0.000641156648195347" />
    </inertial>
    <visual>
      <origin xyz="0 0 0" rpy="0 0 0" />
      <geometry>
        <mesh filename="package://dobot_rviz/meshes/nova5/Link5.STL" />
      </geometry>
      <material name="">
        <color rgba="0.792156862745098 0.819607843137255 0.933333333333333 1" />
      </material>
    </visual>
    <collision>
      <origin xyz="0 0 0" rpy="0 0 0" />
      <geometry>
        <mesh filename="package://dobot_rviz/meshes/nova5/Link5.STL" />
      </geometry>
    </collision>
  </link>
  <joint name="joint5" type="revolute">
    <origin xyz="0 -0.12 0" rpy="1.5708 0 0" />
    <parent link="Link4" />
    <child link="Link5" />
    <axis xyz="0 0 1" />
    <limit lower="-6.28" upper="6.28" effort="0" velocity="0" />
  </joint>

  <link name="Link6">
    <inertial>
      <origin xyz="1.5476173180832E-06 0.000151598525687691 -0.0194592287865595" rpy="0 0 0" />
      <mass value="0.129679940383395" />
      <inertia ixx="5.02803124561327E-05" ixy="6.27222112028976E-11" ixz="3.5128727780266E-12" iyy="5.05400746124736E-05" iyz="5.0343678900728E-08" izz="7.7863015024978E-05" />
    </inertial>
    <visual>
      <origin xyz="0 0 0" rpy="0 0 0" />
      <geometry>
        <mesh filename="package://dobot_rviz/meshes/nova5/Link6.STL" />
      </geometry>
      <material name="">
        <color rgba="0.752941176470588 0.752941176470588 0.752941176470588 1" />
      </material>
    </visual>
    <collision>
      <origin xyz="0 0 0" rpy="0 0 0" />
      <geometry>
        <mesh filename="package://dobot_rviz/meshes/nova5/Link6.STL" />
      </geometry>
    </collision>
  </link>
  <joint name="joint6" type="revolute">
    <origin xyz="0 0.088328 0" rpy="-1.5708 0 0" />
    <parent link="Link5" />
    <child link="Link6" />
    <axis xyz="0 0 1" />
    <limit lower="-6.28" upper="6.28" effort="0" velocity="0" />
  </joint>
  
  ---------------------------------------------------------------------------------------------------------
  <!--                             Costom end effector position                                         -->
  ---------------------------------------------------------------------------------------------------------
  
  <link name="portafilter_offset_link">
    <visual>
      <origin xyz="-0.0415 0.0725 -0.24" rpy="1.8 0 0.0" />
      <geometry>
        <mesh filename="package://dobot_rviz/meshes/nova5/portafilter_b.stl" />
      </geometry>
      <material name="">
        <color rgba="0.752941176470588 0.752941176470588 0.752941176470588 1" />
      </material>
    </visual>
    <!--<collision>
      <origin xyz="-0.0415 0.0725 -0.24" rpy="1.8 0 0.0" />
      <geometry>
        <mesh filename="package://dobot_rviz/meshes/nova5/portafilter_b.stl" />
      </geometry>
    </collision>-->
  </link>
  <joint name="portafilter_offset_joint" type="fixed">
    <parent link="Link6"/>
    <child link="portafilter_offset_link"/>
    <origin xyz="0 0 0.26" rpy="-0.175 0 0"/>
  </joint>
  
  <link name="tool_link"/>
  <joint name="tool_joint" type="fixed">
    <parent link="Link6"/>
    <child link="tool_link"/>
    <origin xyz="0 0 0.1285" rpy="0 0 0"/>
  </joint>
  
  <link name="cup_offset_link"/>
  <joint name="cup_offset_joint" type="fixed">
    <parent link="Link6"/>
    <child link="cup_offset_link"/>
    <origin xyz="0 0 0.15" rpy="0 0 0"/>
  </joint>
  
  <link name="calibration_link"/>
  <joint name="calibration_joint" type="fixed">
    <parent link="Link6"/>
    <child link="calibration_link"/>
    <origin xyz="0 -0.023 0.357" rpy="0 -2.10155463 1.5708"/>
  </joint>
    ---------------------------------------------------------------------------------------------------------
  <!--                             Costom end effector position                                         -->
  ---------------------------------------------------------------------------------------------------------

  <link name="robotiq_85_base_link">
    <inertial>
      <origin xyz="0.00021987 -2.3546E-10 0.030163" rpy="0 0 0" />
      <mass value="0.30915" />
      <inertia ixx="0.00028972" ixy="-5.7879E-10" ixz="-1.8543E-06" iyy="0.00030737" iyz="1.682E-12" izz="0.00019914" />
    </inertial>
    <visual>
      <origin xyz="0 0 0" rpy="0 0 0" />
      <geometry>
        <mesh filename="package://dobot_rviz/meshes/robotiq2f85/robotiq_85_base_link_fine.STL" />
      </geometry>
      <material name="">
        <color rgba="0.1 0.1 0.1 1" />
      </material>
    </visual>
    <collision>
      <origin xyz="0 0 0" rpy="0 0 0" />
      <geometry>
        <mesh filename="package://dobot_rviz/meshes/robotiq2f85/robotiq_85_base_link_fine.STL" />
      </geometry>
    </collision>
  </link>

  <joint name="gripper_mount_joint" type="fixed">
    <origin xyz="0 0 0" rpy="0 0 0"/>
    <parent link="Link6"/>
    <child link="robotiq_85_base_link"/>
  </joint>

  <link name="camera_mount_link">
    <inertial>
      <origin xyz="0.042 0.048 -0.0015" rpy="0 0 3.1416" />
      <mass value="0.30915" />
      <inertia ixx="0.00028972" ixy="-5.7879E-10" ixz="-1.8543E-06" iyy="0.00030737" iyz="1.682E-12" izz="0.00019914" />
    </inertial>
    <visual>
      <origin xyz="0.042 0.048 -0.0015" rpy="0 0 3.1416" />
      <geometry>
        <mesh filename="package://dobot_rviz/meshes/robotiq2f85/camera_mount.STL" />
      </geometry>
      <material name="">
        <color rgba="0.792156862745098 0.819607843137255 0.933333333333333 1" />
      </material>
    </visual>
    <collision>
      <origin xyz="0.042 0.048 -0.0015" rpy="0 0 3.1416" />
      <geometry>
        <mesh filename="package://dobot_rviz/meshes/robotiq2f85/camera_mount.STL" />
      </geometry>
    </collision>
  </link>
  <joint name="camera_mount_joint" type="fixed">
    <origin xyz="0 0 0" rpy="0 0 0"/>
    <parent link="robotiq_85_base_link"/>
    <child link="camera_mount_link"/>
  </joint>

  <link name="camera_link">
    <inertial>
      <origin xyz="0 0 0" rpy="1.5708 0 1.5708"/>
      <mass value="0.30915" />
      <inertia ixx="0.00028972" ixy="-5.7879E-10" ixz="-1.8543E-06" iyy="0.00030737" iyz="1.682E-12" izz="0.00019914" />
    </inertial>
    <visual>
      <origin xyz="0 0 0" rpy="1.5708 0 1.5708"/>
      <geometry>
        <mesh filename="package://dobot_rviz/meshes/robotiq2f85/d435.dae" />
      </geometry>
      <material name="">
        <color rgba="0.792156862745098 0.819607843137255 0.933333333333333 1" />
      </material>
    </visual>
    <collision>
      <origin xyz="0 0 0" rpy="1.5708 0 1.5708"/>
      <geometry>
        <mesh filename="package://dobot_rviz/meshes/robotiq2f85/d435.dae" />
      </geometry>
    </collision>
  </link>
  <joint name="camera_joint" type="fixed">
    <origin xyz="0 -0.0823 0.0285" rpy="0 -1.4108 1.5708" />
    <parent link="camera_mount_link"/>
    <child link="camera_link"/>
  </joint>

  <link name="left_outer_knuckle">
    <inertial>
      <origin xyz="0.0178331863169983 3.68915177224286E-11 0.0021442477325704" rpy="0 0 0" />
      <mass value="0.00684838849434396" />
      <inertia ixx="2.66832029033166E-07" ixy="1.66142314639824E-15" ixz="1.45945633322873E-07" iyy="1.3889233257419E-06" iyz="2.82951161241588E-15" izz="1.26603336914415E-06" />
    </inertial>
    <visual>
      <origin xyz="0 0 0" rpy="0 0 0" />
      <geometry>
        <mesh filename="package://dobot_rviz/meshes/robotiq2f85/outer_knuckle_fine.STL" />
      </geometry>
      <material name="">
        <color rgba="0.1 0.1 0.1 1" />
      </material>
    </visual>
    <collision>
      <origin xyz="0 0 0" rpy="0 0 0" />
      <geometry>
        <mesh filename="package://dobot_rviz/meshes/robotiq2f85/outer_knuckle_fine.STL" />
      </geometry>
    </collision>
  </link>
  <joint name="finger_joint" type="revolute">
    <origin xyz="0.0306011444260539 0 0.0627920162695395" rpy="0 0 0" />
    <parent link="robotiq_85_base_link" />
    <child link="left_outer_knuckle" />
    <axis xyz="0 -1 0" />
    <limit lower="0" upper="0.725" velocity="2.0" effort="1000" />
  </joint>

  <link name="left_outer_finger">
    <inertial>
      <origin xyz="0.00131451599174296 2.88942057994543E-15 0.0215404163180413" rpy="0 0 0" />
      <mass value="0.0273093985570947" />
      <inertia ixx="8.51629628283022E-06" ixy="2.58174336207405E-19" ixz="3.83829504344079E-07" iyy="6.9133328065108E-06" iyz="-7.58589926143789E-19" izz="2.25006832221981E-06" />
    </inertial>
    <visual>
      <origin xyz="0 0 0" rpy="0 0 0" />
      <geometry>
        <mesh filename="package://dobot_rviz/meshes/robotiq2f85/outer_finger_fine.STL" />
      </geometry>
      <material name="">
        <color rgba="0.1 0.1 0.1 1" />
      </material>
    </visual>
    <collision>
      <origin xyz="0 0 0" rpy="0 0 0" />
      <geometry>
        <mesh filename="package://dobot_rviz/meshes/robotiq2f85/outer_finger_fine.STL" />
      </geometry>
    </collision>
  </link>
  <joint name="left_outer_finger_joint" type="fixed">
    <origin xyz="0.0316910442266543 0 -0.00193396375724605" rpy="0 0 0" />
    <parent link="left_outer_knuckle" />
    <child link="left_outer_finger" />
    <axis xyz="0 -1 0" />
  </joint>

  <link name="left_inner_knuckle">
    <inertial>
      <origin xyz="0.017097546626628 -3.93808524389535E-10 0.0224918438201868" rpy="0 0 0" />
      <mass value="0.0110930853895903" />
      <inertia ixx="4.23392770691541E-06" ixy="5.748978936968E-15" ixz="1.78855677119788E-06" iyy="3.96548790524392E-06" iyz="1.05464666369669E-14" izz="3.24068002883007E-06" />
    </inertial>
    <visual>
      <origin xyz="0 0 0" rpy="0 0 0" />
      <geometry>
        <mesh filename="package://dobot_rviz/meshes/robotiq2f85/inner_knuckle_fine.STL" />
      </geometry>
      <material name="">
        <color rgba="0.1 0.1 0.1 1" />
      </material>
    </visual>
    <collision>
      <origin xyz="0 0 0" rpy="0 0 0" />
      <geometry>
        <mesh filename="package://dobot_rviz/meshes/robotiq2f85/inner_knuckle_fine.STL" />
      </geometry>
    </collision>
  </link>
  <joint name="left_inner_knuckle_joint" type="revolute">
    <origin xyz="0.0127000000001501 0 0.0693074999999639" rpy="0 0 0" />
    <parent link="robotiq_85_base_link" />
    <child link="left_inner_knuckle" />
    <axis xyz="0 -1 0" />
    <limit lower="0" upper="0.8757" velocity="2.0" effort="1000" />
    <mimic joint="finger_joint" multiplier="1" offset="0" />
  </joint>

  <link name="left_inner_finger">
    <inertial>
      <origin xyz="0.0060275613594574 -6.29183141465421E-15 0.00669925693133241" rpy="0 0 0" />
      <mass value="0.00724255346165745" />
      <inertia ixx="1.47824274053603E-06" ixy="-3.94884463570303E-19" ixz="-3.45268847648622E-07" iyy="1.70064480838395E-06" iyz="3.5059838910097E-19" izz="4.77151336838364E-07" />
    </inertial>
    <visual>
      <origin xyz="-0.1 0.012 -0.11" rpy="1.57 0 0" />
      <geometry>
        <mesh filename="package://dobot_rviz/meshes/robotiq2f85/fingertips_L.STL" />
      </geometry>
      <material name="">
        <color rgba="0.1 0.1 0.1 1" />
      </material>
    </visual>
    <collision>
      <origin xyz="-0.1 0.012 -0.11" rpy="1.57 0 0" />
      <geometry>
        <mesh filename="package://dobot_rviz/meshes/robotiq2f85/fingertips_L.STL" />
      </geometry>
    </collision>
  </link>
  <joint name="left_inner_finger_joint" type="revolute">
    <origin xyz="0.034585310861294 0 0.0454970193817975" rpy="0 0 0" />
    <parent link="left_inner_knuckle" />
    <child link="left_inner_finger" />
    <axis xyz="0 -1 0" />
    <limit lower="0" upper="0.8757" velocity="2.0" effort="1000" />
    <mimic joint="finger_joint" multiplier="-1" offset="0" />
  </joint>

  <link name="right_inner_knuckle">
    <inertial>
      <origin xyz="0.0168606186773776 3.93808471820465E-10 0.0226699950793434" rpy="0 0 0" />
      <mass value="0.0110930853895903" />
      <inertia ixx="4.27134775939882E-06" ixy="-8.53568456728898E-15" ixz="1.77774229944246E-06" iyy="3.96548790524392E-06" iyz="-8.45108024914164E-15" izz="3.20325997634666E-06" />
    </inertial>
    <visual>
      <origin xyz="0 0 0" rpy="0 0 0" />
      <geometry>
        <mesh filename="package://dobot_rviz/meshes/robotiq2f85/inner_knuckle_fine.STL" />
      </geometry>
      <material name="">
        <color rgba="0.1 0.1 0.1 1" />
      </material>
    </visual>
    <collision>
      <origin xyz="0 0 0" rpy="0 0 0" />
      <geometry>
        <mesh filename="package://dobot_rviz/meshes/robotiq2f85/inner_knuckle_fine.STL" />
      </geometry>
    </collision>
  </link>
  <joint name="right_inner_knuckle_joint" type="revolute">
    <origin xyz="-0.0126999999998499 0 0.0693075000000361" rpy="0 0 3.14159265358979" />
    <parent link="robotiq_85_base_link" />
    <child link="right_inner_knuckle" />
    <axis xyz="0 1 0" />
    <limit lower="0" upper="0.8757" velocity="2.0" effort="1000" />
    <mimic joint="finger_joint" multiplier="-1" offset="0" />
  </joint>

  <link name="right_inner_finger">
    <inertial>
      <origin xyz="0.00602756228812038 -6.47284509480176E-15 0.00669925609578108" rpy="0 0 0" />
      <mass value="0.00724255346165744" />
      <inertia ixx="1.47824283625957E-06" ixy="-3.95952064019123E-19" ixz="-3.45268708875543E-07" iyy="1.70064480838394E-06" iyz="3.55286507960029E-19" izz="4.77151241114822E-07" />
    </inertial>
    <visual>
      <origin xyz="-0.1 0.02 -0.11" rpy="1.57 0 0" />
      <geometry>
        <mesh filename="package://dobot_rviz/meshes/robotiq2f85/fingertips_R.STL" />
      </geometry>
      <material name="">
        <color rgba="0.1 0.1 0.1 1" />
      </material>
    </visual>
    <collision>
      <origin xyz="-0.1 0.02 -0.11" rpy="1.57 0 0" />
      <geometry>
        <mesh filename="package://dobot_rviz/meshes/robotiq2f85/fingertips_R.STL" />
      </geometry>
    </collision>
  </link>
  <joint name="right_inner_finger_joint" type="revolute">
    <origin xyz="0.0341060475457406 0 0.0458573878541688" rpy="0 0 0" />
    <parent link="right_inner_knuckle" />
    <child link="right_inner_finger" />
    <axis xyz="0 1 0" />
    <limit lower="0" upper="0.8757" velocity="2.0" effort="1000" />
    <mimic joint="finger_joint" multiplier="1" offset="0" />
  </joint>

  <link name="right_outer_knuckle">
    <inertial>
      <origin xyz="0.0178097074051638 3.60493211424024E-11 0.00233123458346721" rpy="0 0 0" />
      <mass value="0.00684838849401352" />
      <inertia ixx="2.70004361573169E-07" ixy="1.59579467624491E-15" ixz="1.56396493788199E-07" iyy="1.38892332558312E-06" iyz="2.82357800318817E-15" izz="1.26286103637978E-06" />
    </inertial>
    <visual>
      <origin xyz="0 0 0" rpy="0 0 0" />
      <geometry>
        <mesh filename="package://dobot_rviz/meshes/robotiq2f85/outer_knuckle_fine.STL" />
      </geometry>
      <material name="">
        <color rgba="0.1 0.1 0.1 1" />
      </material>
    </visual>
    <collision>
      <origin xyz="0 0 0" rpy="0 0 0" />
      <geometry>
        <mesh filename="package://dobot_rviz/meshes/robotiq2f85/outer_knuckle_fine.STL" />
      </geometry>
    </collision>
  </link>
  <joint name="right_outer_knuckle_joint" type="revolute">
    <origin xyz="-0.0306011444258893 0 0.0627920162695395" rpy="0 0 3.14159265358979" />
    <parent link="robotiq_85_base_link" />
    <child link="right_outer_knuckle" />
    <axis xyz="0 1 0" />
    <limit lower="0" upper="0.8757" velocity="2.0" effort="1000" />
    <mimic joint="finger_joint" multiplier="-1" offset="0" />
  </joint>

  <link name="right_outer_finger">
    <inertial>
      <origin xyz="0.00108844269639009 -2.611488350845E-15 0.0215530225245502" rpy="0 0 0" />
      <mass value="0.0273093985570947" />
      <inertia ixx="8.52366028592721E-06" ixy="3.41683380899422E-19" ixz="3.18003675694284E-07" iyy="6.91333280651081E-06" iyz="7.37726682706417E-19" izz="2.24270431912283E-06" />
    </inertial>
    <visual>
      <origin xyz="0 0 0" rpy="0 0 0" />
      <geometry>
        <mesh filename="package://dobot_rviz/meshes/robotiq2f85/outer_finger_fine.STL" />
      </geometry>
      <material name="">
        <color rgba="0.1 0.1 0.1 1" />
      </material>
    </visual>
    <collision>
      <origin xyz="0 0 0" rpy="0 0 0" />
      <geometry>
        <mesh filename="package://dobot_rviz/meshes/robotiq2f85/outer_finger_fine.STL" />
      </geometry>
    </collision>
  </link>
  <joint name="right_outer_finger_joint" type="fixed">
    <origin xyz="0.0317095909367246 0 -0.0016013564954687" rpy="0 0 0" />
    <parent link="right_outer_knuckle" />
    <child link="right_outer_finger" />
    <axis xyz="0 1 0" />
  </joint>
  
  <!-- Coffee Machine Link -->
  <link name="coffee_machine">
    <visual>
      <origin xyz="0.43 -0.665 0.221" rpy="0 0 3.1416" />
      <geometry>
        <mesh filename="package://dobot_rviz/meshes/nova5/untitled.stl" scale="1 1 1"/>
      </geometry>
      <material name="">
        <color rgba="0.792156862745098 0.819607843137255 0.933333333333333 1"/>
      </material>
    </visual>
    <collision>
      <origin xyz="0.43 -0.665 0.221" rpy="0 0 3.1416" />
      <geometry>
        <mesh filename="package://dobot_rviz/meshes/nova5/untitled.stl" scale="1 1 1"/>
      </geometry>
    </collision>
  </link>

  <!-- Fixed Joint for Coffee Machine -->
  <joint name="coffee_machine_fixed_joint" type="fixed">
    <parent link="base_link"/>
    <child link="coffee_machine"/>
    <origin xyz="0.0 0.0 0.0" rpy="0 0 0"/>
  </joint>
  
  <!-- Coffee Machine Base Link -->
  <link name="coffee_machine_base">
    <visual>
      <origin xyz="-1.1 -0.64 -0.59" rpy="1.57 0 0" />
      <geometry>
        <mesh filename="package://dobot_rviz/meshes/nova5/coffe_machine_base.stl" scale="1 1 1"/>
      </geometry>
      <material name="">
        <color rgba="0.792156862745098 0.819607843137255 0.933333333333333 1"/>
      </material>
    </visual>
    <collision>
      <origin xyz="-1.1 -0.64 -0.59" rpy="1.57 0 0" />
      <geometry>
        <mesh filename="package://dobot_rviz/meshes/nova5/coffe_machine_base.stl" scale="1 1 1"/>
      </geometry>
    </collision>
  </link>

  <!-- Fixed Joint for Coffee Machine Base -->
  <joint name="coffee_machine_base_fixed_joint" type="fixed">
    <parent link="coffee_machine"/>
    <child link="coffee_machine_base"/>
    <origin xyz="0.0 0.0 0.0" rpy="0 0 0"/>
  </joint>
  

  <!-- Grinder Machine Link -->
  <link name="Grinder_machine">
    <visual>
      <origin xyz="0.66 0.92 -1.55" rpy="1.57 0 -1.57" />
      <geometry>
        <mesh filename="package://dobot_rviz/meshes/nova5/test_grinder.stl" scale="1 1 1"/>
      </geometry>
      <material name="">
        <color rgba="0.792156862745098 0.819607843137255 0.933333333333333 1"/>
      </material>
    </visual>
    <collision>
      <origin xyz="0.66 0.92 -1.55" rpy="1.57 0 -1.57" />
      <geometry>
        <mesh filename="package://dobot_rviz/meshes/nova5/test_grinder.stl" scale="1 1 1"/>
      </geometry>
    </collision>
  </link>

  <!-- Fixed Joint for Grinder Machine -->
  <joint name="Grinder_machine_fixed_joint" type="fixed">
    <parent link="base_link"/>
    <child link="Grinder_machine"/>
    <origin xyz="0.0 0.0 0.0" rpy="0 0 0"/>
  </joint>
  
  <!-- Grinder base Link -->
  <link name="Grinder_base">
    <visual>
      <origin xyz="-0.45 -0.1 -0.55" rpy="1.57 0 -1.57" />
      <geometry>
        <mesh filename="package://dobot_rviz/meshes/nova5/stand.stl" scale="1 1 1"/>
      </geometry>
      <material name="">
        <color rgba="0.792156862745098 0.819607843137255 0.933333333333333 1"/>
      </material>
    </visual>
    <collision>
      <origin xyz="-0.45 -0.1 -0.55" rpy="1.57 0 -1.57" />
      <geometry>
        <mesh filename="package://dobot_rviz/meshes/nova5/stand.stl" scale="1 1 1"/>
      </geometry>
    </collision>
  </link>

  <!-- Fixed Joint for Grinder base -->
  <joint name="Grinder_base_fixed_joint" type="fixed">
    <parent link="base_link"/>
    <child link="Grinder_base"/>
    <origin xyz="0.0 0.0 0.0" rpy="0 0 0"/>
  </joint>
  
  <!-- Base Link -->
  <link name="base">
    <visual>
      <origin xyz="0.4 0.4 -0.54" rpy="1.57 0 -1.57" />
      <geometry>
        <mesh filename="package://dobot_rviz/meshes/nova5/arm_base.stl" scale="1 1 1"/>
      </geometry>
      <material name="">
        <color rgba="0.792156862745098 0.819607843137255 0.933333333333333 1"/>
      </material>
    </visual>
    <collision>
      <origin xyz="0.4 0.4 -0.54" rpy="1.57 0 -1.57" />
      <geometry>
        <mesh filename="package://dobot_rviz/meshes/nova5/arm_base.stl" scale="1 1 1"/>
      </geometry>
    </collision>
  </link>

  <!-- Fixed Joint for Base -->
  <joint name="base_fixed_joint" type="fixed">
    <parent link="base_link"/>
    <child link="base"/>
    <origin xyz="0.0 0.0 0.0" rpy="0 0 0"/>
  </joint>
</robot>

